ERROR 2025-05-31 19:24:14,179 log 22 140288890869568 Internal Server Error: /admin/api/politicapago/add/
Traceback (most recent call last):
  File "/usr/local/lib/python3.10/site-packages/django/core/handlers/exception.py", line 55, in inner
    response = get_response(request)
  File "/usr/local/lib/python3.10/site-packages/django/core/handlers/base.py", line 197, in _get_response
    response = wrapped_callback(request, *callback_args, **callback_kwargs)
  File "/usr/local/lib/python3.10/site-packages/django/contrib/admin/options.py", line 718, in wrapper
    return self.admin_site.admin_view(view)(*args, **kwargs)
  File "/usr/local/lib/python3.10/site-packages/django/utils/decorators.py", line 188, in _view_wrapper
    result = _process_exception(request, e)
  File "/usr/local/lib/python3.10/site-packages/django/utils/decorators.py", line 186, in _view_wrapper
    response = view_func(request, *args, **kwargs)
  File "/usr/local/lib/python3.10/site-packages/django/views/decorators/cache.py", line 80, in _view_wrapper
    response = view_func(request, *args, **kwargs)
  File "/usr/local/lib/python3.10/site-packages/django/contrib/admin/sites.py", line 241, in inner
    return view(request, *args, **kwargs)
  File "/usr/local/lib/python3.10/site-packages/django/contrib/admin/options.py", line 1961, in add_view
    return self.changeform_view(request, None, form_url, extra_context)
  File "/usr/local/lib/python3.10/site-packages/django/utils/decorators.py", line 48, in _wrapper
    return bound_method(*args, **kwargs)
  File "/usr/local/lib/python3.10/site-packages/django/utils/decorators.py", line 188, in _view_wrapper
    result = _process_exception(request, e)
  File "/usr/local/lib/python3.10/site-packages/django/utils/decorators.py", line 186, in _view_wrapper
    response = view_func(request, *args, **kwargs)
  File "/usr/local/lib/python3.10/site-packages/django/contrib/admin/options.py", line 1820, in changeform_view
    return self._changeform_view(request, object_id, form_url, extra_context)
  File "/usr/local/lib/python3.10/site-packages/django/contrib/admin/options.py", line 1870, in _changeform_view
    if all_valid(formsets) and form_validated:
  File "/usr/local/lib/python3.10/site-packages/django/forms/formsets.py", line 579, in all_valid
    return all([formset.is_valid() for formset in formsets])
  File "/usr/local/lib/python3.10/site-packages/django/forms/formsets.py", line 579, in <listcomp>
    return all([formset.is_valid() for formset in formsets])
  File "/usr/local/lib/python3.10/site-packages/django/forms/formsets.py", line 384, in is_valid
    self.errors
  File "/usr/local/lib/python3.10/site-packages/django/forms/formsets.py", line 366, in errors
    self.full_clean()
  File "/usr/local/lib/python3.10/site-packages/django/forms/formsets.py", line 429, in full_clean
    form_errors = form.errors
  File "/usr/local/lib/python3.10/site-packages/django/forms/forms.py", line 192, in errors
    self.full_clean()
  File "/usr/local/lib/python3.10/site-packages/django/forms/forms.py", line 327, in full_clean
    self._post_clean()
  File "/usr/local/lib/python3.10/site-packages/django/forms/models.py", line 498, in _post_clean
    self.instance.full_clean(exclude=exclude, validate_unique=False)
  File "/usr/local/lib/python3.10/site-packages/django/db/models/base.py", line 1626, in full_clean
    self.clean()
  File "/app/api/models/politicasPago.py", line 130, in clean
    existing = PoliticaIncluye.objects.filter(
  File "/usr/local/lib/python3.10/site-packages/django/db/models/manager.py", line 87, in manager_method
    return getattr(self.get_queryset(), name)(*args, **kwargs)
  File "/usr/local/lib/python3.10/site-packages/django/db/models/query.py", line 1476, in filter
    return self._filter_or_exclude(False, args, kwargs)
  File "/usr/local/lib/python3.10/site-packages/django/db/models/query.py", line 1494, in _filter_or_exclude
    clone._filter_or_exclude_inplace(negate, args, kwargs)
  File "/usr/local/lib/python3.10/site-packages/django/db/models/query.py", line 1501, in _filter_or_exclude_inplace
    self._query.add_q(Q(*args, **kwargs))
  File "/usr/local/lib/python3.10/site-packages/django/db/models/sql/query.py", line 1609, in add_q
    clause, _ = self._add_q(q_object, self.used_aliases)
  File "/usr/local/lib/python3.10/site-packages/django/db/models/sql/query.py", line 1641, in _add_q
    child_clause, needed_inner = self.build_filter(
  File "/usr/local/lib/python3.10/site-packages/django/db/models/sql/query.py", line 1555, in build_filter
    condition = self.build_lookup(lookups, col, value)
  File "/usr/local/lib/python3.10/site-packages/django/db/models/sql/query.py", line 1385, in build_lookup
    lookup = lookup_class(lhs, rhs)
  File "/usr/local/lib/python3.10/site-packages/django/db/models/lookups.py", line 30, in __init__
    self.rhs = self.get_prep_lookup()
  File "/usr/local/lib/python3.10/site-packages/django/db/models/fields/related_lookups.py", line 147, in get_prep_lookup
    self.rhs = get_normalized_value(self.rhs, self.lhs)[0]
  File "/usr/local/lib/python3.10/site-packages/django/db/models/fields/related_lookups.py", line 45, in get_normalized_value
    raise ValueError("Model instances passed to related filters must be saved.")
ValueError: Model instances passed to related filters must be saved.
ERROR 2025-05-31 19:36:12,335 log 26 140145412167488 Internal Server Error: /admin/api/politicapago/add/
Traceback (most recent call last):
  File "/usr/local/lib/python3.10/site-packages/django/core/handlers/exception.py", line 55, in inner
    response = get_response(request)
  File "/usr/local/lib/python3.10/site-packages/django/core/handlers/base.py", line 197, in _get_response
    response = wrapped_callback(request, *callback_args, **callback_kwargs)
  File "/usr/local/lib/python3.10/site-packages/django/contrib/admin/options.py", line 718, in wrapper
    return self.admin_site.admin_view(view)(*args, **kwargs)
  File "/usr/local/lib/python3.10/site-packages/django/utils/decorators.py", line 188, in _view_wrapper
    result = _process_exception(request, e)
  File "/usr/local/lib/python3.10/site-packages/django/utils/decorators.py", line 186, in _view_wrapper
    response = view_func(request, *args, **kwargs)
  File "/usr/local/lib/python3.10/site-packages/django/views/decorators/cache.py", line 80, in _view_wrapper
    response = view_func(request, *args, **kwargs)
  File "/usr/local/lib/python3.10/site-packages/django/contrib/admin/sites.py", line 241, in inner
    return view(request, *args, **kwargs)
  File "/usr/local/lib/python3.10/site-packages/django/contrib/admin/options.py", line 1961, in add_view
    return self.changeform_view(request, None, form_url, extra_context)
  File "/usr/local/lib/python3.10/site-packages/django/utils/decorators.py", line 48, in _wrapper
    return bound_method(*args, **kwargs)
  File "/usr/local/lib/python3.10/site-packages/django/utils/decorators.py", line 188, in _view_wrapper
    result = _process_exception(request, e)
  File "/usr/local/lib/python3.10/site-packages/django/utils/decorators.py", line 186, in _view_wrapper
    response = view_func(request, *args, **kwargs)
  File "/usr/local/lib/python3.10/site-packages/django/contrib/admin/options.py", line 1820, in changeform_view
    return self._changeform_view(request, object_id, form_url, extra_context)
  File "/usr/local/lib/python3.10/site-packages/django/contrib/admin/options.py", line 1870, in _changeform_view
    if all_valid(formsets) and form_validated:
  File "/usr/local/lib/python3.10/site-packages/django/forms/formsets.py", line 579, in all_valid
    return all([formset.is_valid() for formset in formsets])
  File "/usr/local/lib/python3.10/site-packages/django/forms/formsets.py", line 579, in <listcomp>
    return all([formset.is_valid() for formset in formsets])
  File "/usr/local/lib/python3.10/site-packages/django/forms/formsets.py", line 384, in is_valid
    self.errors
  File "/usr/local/lib/python3.10/site-packages/django/forms/formsets.py", line 366, in errors
    self.full_clean()
  File "/usr/local/lib/python3.10/site-packages/django/forms/formsets.py", line 429, in full_clean
    form_errors = form.errors
  File "/usr/local/lib/python3.10/site-packages/django/forms/forms.py", line 192, in errors
    self.full_clean()
  File "/usr/local/lib/python3.10/site-packages/django/forms/forms.py", line 327, in full_clean
    self._post_clean()
  File "/usr/local/lib/python3.10/site-packages/django/forms/models.py", line 498, in _post_clean
    self.instance.full_clean(exclude=exclude, validate_unique=False)
  File "/usr/local/lib/python3.10/site-packages/django/db/models/base.py", line 1626, in full_clean
    self.clean()
  File "/app/api/models/politicasPago.py", line 130, in clean
    existing = PoliticaIncluye.objects.filter(
  File "/usr/local/lib/python3.10/site-packages/django/db/models/manager.py", line 87, in manager_method
    return getattr(self.get_queryset(), name)(*args, **kwargs)
  File "/usr/local/lib/python3.10/site-packages/django/db/models/query.py", line 1476, in filter
    return self._filter_or_exclude(False, args, kwargs)
  File "/usr/local/lib/python3.10/site-packages/django/db/models/query.py", line 1494, in _filter_or_exclude
    clone._filter_or_exclude_inplace(negate, args, kwargs)
  File "/usr/local/lib/python3.10/site-packages/django/db/models/query.py", line 1501, in _filter_or_exclude_inplace
    self._query.add_q(Q(*args, **kwargs))
  File "/usr/local/lib/python3.10/site-packages/django/db/models/sql/query.py", line 1609, in add_q
    clause, _ = self._add_q(q_object, self.used_aliases)
  File "/usr/local/lib/python3.10/site-packages/django/db/models/sql/query.py", line 1641, in _add_q
    child_clause, needed_inner = self.build_filter(
  File "/usr/local/lib/python3.10/site-packages/django/db/models/sql/query.py", line 1555, in build_filter
    condition = self.build_lookup(lookups, col, value)
  File "/usr/local/lib/python3.10/site-packages/django/db/models/sql/query.py", line 1385, in build_lookup
    lookup = lookup_class(lhs, rhs)
  File "/usr/local/lib/python3.10/site-packages/django/db/models/lookups.py", line 30, in __init__
    self.rhs = self.get_prep_lookup()
  File "/usr/local/lib/python3.10/site-packages/django/db/models/fields/related_lookups.py", line 147, in get_prep_lookup
    self.rhs = get_normalized_value(self.rhs, self.lhs)[0]
  File "/usr/local/lib/python3.10/site-packages/django/db/models/fields/related_lookups.py", line 45, in get_normalized_value
    raise ValueError("Model instances passed to related filters must be saved.")
ValueError: Model instances passed to related filters must be saved.
WARNING 2025-05-31 20:01:17,273 log 26 140145412167488 Bad Request: /api/contenidos/
WARNING 2025-05-31 20:01:17,494 log 29 140145412167488 Bad Request: /api/contenidos/
WARNING 2025-05-31 20:24:44,155 log 26 140145412167488 Bad Request: /api/contenidos/
WARNING 2025-05-31 20:24:44,154 log 28 140145412167488 Bad Request: /api/contenidos/
WARNING 2025-05-31 20:44:44,348 log 23 139740515034944 Bad Request: /api/contenidos/
WARNING 2025-05-31 20:44:44,349 log 20 139740515034944 Bad Request: /api/contenidos/
INFO 2025-05-31 20:54:48,143 services 23 139740515034944 StripePaymentService inicializado
ERROR 2025-05-31 20:54:48,155 log 23 139740515034944 Internal Server Error: /api/reservations/create-new/
