
ERROR 2025-05-27 18:51:09,162 log 23 140068149401408 Internal Server Error: /admin/payments/pagostripe/add/
Traceback (most recent call last):
  File "/usr/local/lib/python3.10/site-packages/django/db/models/options.py", line 676, in get_field
    return self.fields_map[field_name]
KeyError: 'importe_disponible_reembolso_display'

During handling of the above exception, another exception occurred:

Traceback (most recent call last):
  File "/usr/local/lib/python3.10/site-packages/django/contrib/admin/utils.py", line 290, in lookup_field
    f = _get_non_gfk_field(opts, name)
  File "/usr/local/lib/python3.10/site-packages/django/contrib/admin/utils.py", line 330, in _get_non_gfk_field
    field = opts.get_field(name)
  File "/usr/local/lib/python3.10/site-packages/django/db/models/options.py", line 678, in get_field
    raise FieldDoesNotExist(
django.core.exceptions.FieldDoesNotExist: PagoStripe has no field named 'importe_disponible_reembolso_display'

During handling of the above exception, another exception occurred:

Traceback (most recent call last):
  File "/usr/local/lib/python3.10/site-packages/django/core/handlers/exception.py", line 55, in inner
    response = get_response(request)
  File "/usr/local/lib/python3.10/site-packages/django/core/handlers/base.py", line 220, in _get_response
    response = response.render()
  File "/usr/local/lib/python3.10/site-packages/django/template/response.py", line 114, in render
    self.content = self.rendered_content
  File "/usr/local/lib/python3.10/site-packages/django/template/response.py", line 92, in rendered_content
    return template.render(context, self._request)
  File "/usr/local/lib/python3.10/site-packages/django/template/backends/django.py", line 107, in render
    return self.template.render(context)
  File "/usr/local/lib/python3.10/site-packages/django/template/base.py", line 171, in render
    return self._render(context)
  File "/usr/local/lib/python3.10/site-packages/django/template/base.py", line 163, in _render
    return self.nodelist.render(context)
  File "/usr/local/lib/python3.10/site-packages/django/template/base.py", line 1008, in render
    return SafeString("".join([node.render_annotated(context) for node in self]))
  File "/usr/local/lib/python3.10/site-packages/django/template/base.py", line 1008, in <listcomp>
    return SafeString("".join([node.render_annotated(context) for node in self]))
  File "/usr/local/lib/python3.10/site-packages/django/template/base.py", line 969, in render_annotated
    return self.render(context)
  File "/usr/local/lib/python3.10/site-packages/django/template/loader_tags.py", line 159, in render
    return compiled_parent._render(context)
  File "/usr/local/lib/python3.10/site-packages/django/template/base.py", line 163, in _render
    return self.nodelist.render(context)
  File "/usr/local/lib/python3.10/site-packages/django/template/base.py", line 1008, in render
    return SafeString("".join([node.render_annotated(context) for node in self]))
  File "/usr/local/lib/python3.10/site-packages/django/template/base.py", line 1008, in <listcomp>
    return SafeString("".join([node.render_annotated(context) for node in self]))
  File "/usr/local/lib/python3.10/site-packages/django/template/base.py", line 969, in render_annotated
    return self.render(context)
  File "/usr/local/lib/python3.10/site-packages/django/template/loader_tags.py", line 159, in render
    return compiled_parent._render(context)
  File "/usr/local/lib/python3.10/site-packages/django/template/base.py", line 163, in _render
    return self.nodelist.render(context)
  File "/usr/local/lib/python3.10/site-packages/django/template/base.py", line 1008, in render
    return SafeString("".join([node.render_annotated(context) for node in self]))
  File "/usr/local/lib/python3.10/site-packages/django/template/base.py", line 1008, in <listcomp>
    return SafeString("".join([node.render_annotated(context) for node in self]))
  File "/usr/local/lib/python3.10/site-packages/django/template/base.py", line 969, in render_annotated
    return self.render(context)
  File "/usr/local/lib/python3.10/site-packages/django/template/loader_tags.py", line 65, in render
    result = block.nodelist.render(context)
  File "/usr/local/lib/python3.10/site-packages/django/template/base.py", line 1008, in render
    return SafeString("".join([node.render_annotated(context) for node in self]))
  File "/usr/local/lib/python3.10/site-packages/django/template/base.py", line 1008, in <listcomp>
    return SafeString("".join([node.render_annotated(context) for node in self]))
  File "/usr/local/lib/python3.10/site-packages/django/template/base.py", line 969, in render_annotated
    return self.render(context)
  File "/usr/local/lib/python3.10/site-packages/django/template/loader_tags.py", line 65, in render
    result = block.nodelist.render(context)
  File "/usr/local/lib/python3.10/site-packages/django/template/base.py", line 1008, in render
    return SafeString("".join([node.render_annotated(context) for node in self]))
  File "/usr/local/lib/python3.10/site-packages/django/template/base.py", line 1008, in <listcomp>
    return SafeString("".join([node.render_annotated(context) for node in self]))
  File "/usr/local/lib/python3.10/site-packages/django/template/base.py", line 969, in render_annotated
    return self.render(context)
  File "/usr/local/lib/python3.10/site-packages/django/template/defaulttags.py", line 243, in render
    nodelist.append(node.render_annotated(context))
  File "/usr/local/lib/python3.10/site-packages/django/template/base.py", line 969, in render_annotated
    return self.render(context)
  File "/usr/local/lib/python3.10/site-packages/django/template/loader_tags.py", line 210, in render
    return template.render(context)
  File "/usr/local/lib/python3.10/site-packages/django/template/base.py", line 173, in render
    return self._render(context)
  File "/usr/local/lib/python3.10/site-packages/django/template/base.py", line 163, in _render
    return self.nodelist.render(context)
  File "/usr/local/lib/python3.10/site-packages/django/template/base.py", line 1008, in render
    return SafeString("".join([node.render_annotated(context) for node in self]))
  File "/usr/local/lib/python3.10/site-packages/django/template/base.py", line 1008, in <listcomp>
    return SafeString("".join([node.render_annotated(context) for node in self]))
  File "/usr/local/lib/python3.10/site-packages/django/template/base.py", line 969, in render_annotated
    return self.render(context)
  File "/usr/local/lib/python3.10/site-packages/django/template/defaulttags.py", line 243, in render
    nodelist.append(node.render_annotated(context))
  File "/usr/local/lib/python3.10/site-packages/django/template/base.py", line 969, in render_annotated
    return self.render(context)
  File "/usr/local/lib/python3.10/site-packages/django/template/defaulttags.py", line 243, in render
    nodelist.append(node.render_annotated(context))
  File "/usr/local/lib/python3.10/site-packages/django/template/base.py", line 969, in render_annotated
    return self.render(context)
  File "/usr/local/lib/python3.10/site-packages/django/template/defaulttags.py", line 327, in render
    return nodelist.render(context)
  File "/usr/local/lib/python3.10/site-packages/django/template/base.py", line 1008, in render
    return SafeString("".join([node.render_annotated(context) for node in self]))
  File "/usr/local/lib/python3.10/site-packages/django/template/base.py", line 1008, in <listcomp>
    return SafeString("".join([node.render_annotated(context) for node in self]))
  File "/usr/local/lib/python3.10/site-packages/django/template/base.py", line 969, in render_annotated
    return self.render(context)
  File "/usr/local/lib/python3.10/site-packages/django/template/defaulttags.py", line 327, in render
    return nodelist.render(context)
  File "/usr/local/lib/python3.10/site-packages/django/template/base.py", line 1008, in render
    return SafeString("".join([node.render_annotated(context) for node in self]))
  File "/usr/local/lib/python3.10/site-packages/django/template/base.py", line 1008, in <listcomp>
    return SafeString("".join([node.render_annotated(context) for node in self]))
  File "/usr/local/lib/python3.10/site-packages/django/template/base.py", line 969, in render_annotated
    return self.render(context)
  File "/usr/local/lib/python3.10/site-packages/django/template/base.py", line 1067, in render
    output = self.filter_expression.resolve(context)
  File "/usr/local/lib/python3.10/site-packages/django/template/base.py", line 718, in resolve
    obj = self.var.resolve(context)
  File "/usr/local/lib/python3.10/site-packages/django/template/base.py", line 850, in resolve
    value = self._resolve_lookup(context)
  File "/usr/local/lib/python3.10/site-packages/django/template/base.py", line 917, in _resolve_lookup
    current = current()
  File "/usr/local/lib/python3.10/site-packages/django/contrib/admin/helpers.py", line 275, in contents
    f, attr, value = lookup_field(field, obj, model_admin)
  File "/usr/local/lib/python3.10/site-packages/django/contrib/admin/utils.py", line 299, in lookup_field
    value = attr(obj)
  File "/app/payments/admin.py", line 216, in importe_disponible_reembolso_display
    importe = obj.importe_disponible_reembolso
  File "/app/payments/models.py", line 196, in importe_disponible_reembolso
    return self.importe - self.importe_reembolsado
TypeError: unsupported operand type(s) for -: 'NoneType' and 'decimal.Decimal'
WARNING 2025-05-27 18:55:27,638 log 22 140300626138944 Forbidden: /api/vehiculos/disponibilidad/
WARNING 2025-05-27 19:09:13,447 log 20 140300626138944 Forbidden: /api/vehiculos/disponibilidad/
WARNING 2025-05-27 19:21:55,738 log 21 140250632677184 Forbidden: /api/vehiculos/disponibilidad/
WARNING 2025-05-27 19:22:32,303 log 23 140250632677184 Forbidden: /api/vehiculos/disponibilidad/
WARNING 2025-05-27 19:22:33,313 log 20 140250632677184 Forbidden: /api/vehiculos/disponibilidad/
WARNING 2025-05-27 19:23:52,455 log 22 140250632677184 Bad Request: /api/vehiculos/disponibilidad/
WARNING 2025-05-27 19:24:04,806 log 23 140250632677184 Bad Request: /api/vehiculos/disponibilidad/
ERROR 2025-05-27 19:28:46,165 log 23 140250632677184 Internal Server Error: /admin/api/extras/
Traceback (most recent call last):
  File "/usr/local/lib/python3.10/site-packages/django/db/models/options.py", line 676, in get_field
    return self.fields_map[field_name]
KeyError: 'get_reservas_count'

During handling of the above exception, another exception occurred:

Traceback (most recent call last):
  File "/usr/local/lib/python3.10/site-packages/django/contrib/admin/utils.py", line 290, in lookup_field
    f = _get_non_gfk_field(opts, name)
  File "/usr/local/lib/python3.10/site-packages/django/contrib/admin/utils.py", line 330, in _get_non_gfk_field
    field = opts.get_field(name)
  File "/usr/local/lib/python3.10/site-packages/django/db/models/options.py", line 678, in get_field
    raise FieldDoesNotExist(
django.core.exceptions.FieldDoesNotExist: Extras has no field named 'get_reservas_count'

During handling of the above exception, another exception occurred:

Traceback (most recent call last):
  File "/usr/local/lib/python3.10/site-packages/django/core/handlers/exception.py", line 55, in inner
    response = get_response(request)
  File "/usr/local/lib/python3.10/site-packages/django/core/handlers/base.py", line 220, in _get_response
    response = response.render()
  File "/usr/local/lib/python3.10/site-packages/django/template/response.py", line 114, in render
    self.content = self.rendered_content
  File "/usr/local/lib/python3.10/site-packages/django/template/response.py", line 92, in rendered_content
    return template.render(context, self._request)
  File "/usr/local/lib/python3.10/site-packages/django/template/backends/django.py", line 107, in render
    return self.template.render(context)
  File "/usr/local/lib/python3.10/site-packages/django/template/base.py", line 171, in render
    return self._render(context)
  File "/usr/local/lib/python3.10/site-packages/django/template/base.py", line 163, in _render
    return self.nodelist.render(context)
  File "/usr/local/lib/python3.10/site-packages/django/template/base.py", line 1008, in render
    return SafeString("".join([node.render_annotated(context) for node in self]))
  File "/usr/local/lib/python3.10/site-packages/django/template/base.py", line 1008, in <listcomp>
    return SafeString("".join([node.render_annotated(context) for node in self]))
  File "/usr/local/lib/python3.10/site-packages/django/template/base.py", line 969, in render_annotated
    return self.render(context)
  File "/usr/local/lib/python3.10/site-packages/django/template/loader_tags.py", line 159, in render
    return compiled_parent._render(context)
  File "/usr/local/lib/python3.10/site-packages/django/template/base.py", line 163, in _render
    return self.nodelist.render(context)
  File "/usr/local/lib/python3.10/site-packages/django/template/base.py", line 1008, in render
    return SafeString("".join([node.render_annotated(context) for node in self]))
  File "/usr/local/lib/python3.10/site-packages/django/template/base.py", line 1008, in <listcomp>
    return SafeString("".join([node.render_annotated(context) for node in self]))
  File "/usr/local/lib/python3.10/site-packages/django/template/base.py", line 969, in render_annotated
    return self.render(context)
  File "/usr/local/lib/python3.10/site-packages/django/template/loader_tags.py", line 159, in render
    return compiled_parent._render(context)
  File "/usr/local/lib/python3.10/site-packages/django/template/base.py", line 163, in _render
    return self.nodelist.render(context)
  File "/usr/local/lib/python3.10/site-packages/django/template/base.py", line 1008, in render
    return SafeString("".join([node.render_annotated(context) for node in self]))
  File "/usr/local/lib/python3.10/site-packages/django/template/base.py", line 1008, in <listcomp>
    return SafeString("".join([node.render_annotated(context) for node in self]))
  File "/usr/local/lib/python3.10/site-packages/django/template/base.py", line 969, in render_annotated
    return self.render(context)
  File "/usr/local/lib/python3.10/site-packages/django/template/loader_tags.py", line 65, in render
    result = block.nodelist.render(context)
  File "/usr/local/lib/python3.10/site-packages/django/template/base.py", line 1008, in render
    return SafeString("".join([node.render_annotated(context) for node in self]))
  File "/usr/local/lib/python3.10/site-packages/django/template/base.py", line 1008, in <listcomp>
    return SafeString("".join([node.render_annotated(context) for node in self]))
  File "/usr/local/lib/python3.10/site-packages/django/template/base.py", line 969, in render_annotated
    return self.render(context)
  File "/usr/local/lib/python3.10/site-packages/django/template/loader_tags.py", line 65, in render
    result = block.nodelist.render(context)
  File "/usr/local/lib/python3.10/site-packages/django/template/base.py", line 1008, in render
    return SafeString("".join([node.render_annotated(context) for node in self]))
  File "/usr/local/lib/python3.10/site-packages/django/template/base.py", line 1008, in <listcomp>
    return SafeString("".join([node.render_annotated(context) for node in self]))
  File "/usr/local/lib/python3.10/site-packages/django/template/base.py", line 969, in render_annotated
    return self.render(context)
  File "/usr/local/lib/python3.10/site-packages/django/contrib/admin/templatetags/base.py", line 45, in render
    return super().render(context)
  File "/usr/local/lib/python3.10/site-packages/django/template/library.py", line 258, in render
    _dict = self.func(*resolved_args, **resolved_kwargs)
  File "/usr/local/lib/python3.10/site-packages/django/contrib/admin/templatetags/admin_list.py", line 346, in result_list
    "results": list(results(cl)),
  File "/usr/local/lib/python3.10/site-packages/django/contrib/admin/templatetags/admin_list.py", line 322, in results
    yield ResultList(None, items_for_result(cl, res, None))
  File "/usr/local/lib/python3.10/site-packages/django/contrib/admin/templatetags/admin_list.py", line 313, in __init__
    super().__init__(*items)
  File "/usr/local/lib/python3.10/site-packages/django/contrib/admin/templatetags/admin_list.py", line 218, in items_for_result
    f, attr, value = lookup_field(field_name, result, cl.model_admin)
  File "/usr/local/lib/python3.10/site-packages/django/contrib/admin/utils.py", line 299, in lookup_field
    value = attr(obj)
  File "/app/api/admin.py", line 1524, in get_reservas_count
    count = obj.reservaextra_set.count()
AttributeError: 'Extras' object has no attribute 'reservaextra_set'
WARNING 2025-05-27 19:44:09,934 log 24 139806899943232 Forbidden: /api/vehiculos/disponibilidad/
WARNING 2025-05-27 19:55:02,586 log 20 140386406905664 Forbidden: /api/vehiculos/disponibilidad/
WARNING 2025-05-28 15:03:34,557 log 24 140625592600384 Forbidden: /api/vehiculos/disponibilidad/
WARNING 2025-05-28 15:04:07,816 log 22 140625592600384 Method Not Allowed: /api/vehiculos/disponibilidad/
WARNING 2025-05-28 15:04:24,568 log 23 140625592600384 Forbidden: /api/vehiculos/disponibilidad/
WARNING 2025-05-28 15:13:59,783 log 22 139672816273216 Forbidden: /api/vehiculos/disponibilidad/
WARNING 2025-05-28 15:19:32,413 log 22 139672816273216 Forbidden: /api/vehiculos/disponibilidad/
WARNING 2025-05-28 15:19:32,452 log 23 139672816273216 Forbidden: /api/vehiculos/disponibilidad/
ERROR 2025-05-28 15:29:30,879 log 20 140662761965376 Internal Server Error: /admin/api/lugar/
Traceback (most recent call last):
  File "/usr/local/lib/python3.10/site-packages/django/core/handlers/exception.py", line 55, in inner
    response = get_response(request)
  File "/usr/local/lib/python3.10/site-packages/django/core/handlers/base.py", line 197, in _get_response
    response = wrapped_callback(request, *callback_args, **callback_kwargs)
  File "/usr/local/lib/python3.10/site-packages/django/contrib/admin/options.py", line 718, in wrapper
    return self.admin_site.admin_view(view)(*args, **kwargs)
  File "/usr/local/lib/python3.10/site-packages/django/utils/decorators.py", line 188, in _view_wrapper
    result = _process_exception(request, e)
  File "/usr/local/lib/python3.10/site-packages/django/utils/decorators.py", line 186, in _view_wrapper
    response = view_func(request, *args, **kwargs)
  File "/usr/local/lib/python3.10/site-packages/django/views/decorators/cache.py", line 80, in _view_wrapper
    response = view_func(request, *args, **kwargs)
  File "/usr/local/lib/python3.10/site-packages/django/contrib/admin/sites.py", line 241, in inner
    return view(request, *args, **kwargs)
  File "/usr/local/lib/python3.10/site-packages/django/utils/decorators.py", line 48, in _wrapper
    return bound_method(*args, **kwargs)
  File "/usr/local/lib/python3.10/site-packages/django/utils/decorators.py", line 188, in _view_wrapper
    result = _process_exception(request, e)
  File "/usr/local/lib/python3.10/site-packages/django/utils/decorators.py", line 186, in _view_wrapper
    response = view_func(request, *args, **kwargs)
  File "/usr/local/lib/python3.10/site-packages/django/contrib/admin/options.py", line 2001, in changelist_view
    cl = self.get_changelist_instance(request)
  File "/usr/local/lib/python3.10/site-packages/django/contrib/admin/options.py", line 866, in get_changelist_instance
    return ChangeList(
  File "/usr/local/lib/python3.10/site-packages/django/contrib/admin/views/main.py", line 91, in __init__
    self.root_queryset = model_admin.get_queryset(request)
  File "/app/api/admin.py", line 63, in wrapper
    result = func(self, request, *args, **kwargs)
  File "/app/api/admin.py", line 1038, in get_queryset
    return super().get_queryset(request).select_related('direccion').annotate(
  File "/usr/local/lib/python3.10/site-packages/django/db/models/query.py", line 1630, in annotate
    return self._annotate(args, kwargs, select=True)
  File "/usr/local/lib/python3.10/site-packages/django/db/models/query.py", line 1680, in _annotate
    clone.query.add_annotation(
  File "/usr/local/lib/python3.10/site-packages/django/db/models/sql/query.py", line 1194, in add_annotation
    annotation = annotation.resolve_expression(self, allow_joins=True, reuse=None)
  File "/usr/local/lib/python3.10/site-packages/django/db/models/expressions.py", line 753, in resolve_expression
    lhs = self.lhs.resolve_expression(
  File "/usr/local/lib/python3.10/site-packages/django/db/models/aggregates.py", line 63, in resolve_expression
    c = super().resolve_expression(query, allow_joins, reuse, summarize)
  File "/usr/local/lib/python3.10/site-packages/django/db/models/expressions.py", line 1073, in resolve_expression
    c.source_expressions[pos] = arg.resolve_expression(
  File "/usr/local/lib/python3.10/site-packages/django/db/models/expressions.py", line 895, in resolve_expression
    return query.resolve_ref(self.name, allow_joins, reuse, summarize)
  File "/usr/local/lib/python3.10/site-packages/django/db/models/sql/query.py", line 2010, in resolve_ref
    join_info = self.setup_joins(
  File "/usr/local/lib/python3.10/site-packages/django/db/models/sql/query.py", line 1863, in setup_joins
    path, final_field, targets, rest = self.names_to_path(
  File "/usr/local/lib/python3.10/site-packages/django/db/models/sql/query.py", line 1768, in names_to_path
    raise FieldError(
django.core.exceptions.FieldError: Cannot resolve keyword 'reservas_recogida' into field. Choices are: created_at, devoluciones, direccion, direccion_id, email, icono_url, id, latitud, longitud, nombre, recogidas, telefono, updated_at
ERROR 2025-05-28 15:34:05,738 log 20 140662761965376 Internal Server Error: /admin/api/lugar/
Traceback (most recent call last):
  File "/usr/local/lib/python3.10/site-packages/django/core/handlers/exception.py", line 55, in inner
    response = get_response(request)
  File "/usr/local/lib/python3.10/site-packages/django/core/handlers/base.py", line 197, in _get_response
    response = wrapped_callback(request, *callback_args, **callback_kwargs)
  File "/usr/local/lib/python3.10/site-packages/django/contrib/admin/options.py", line 718, in wrapper
    return self.admin_site.admin_view(view)(*args, **kwargs)
  File "/usr/local/lib/python3.10/site-packages/django/utils/decorators.py", line 188, in _view_wrapper
    result = _process_exception(request, e)
  File "/usr/local/lib/python3.10/site-packages/django/utils/decorators.py", line 186, in _view_wrapper
    response = view_func(request, *args, **kwargs)
  File "/usr/local/lib/python3.10/site-packages/django/views/decorators/cache.py", line 80, in _view_wrapper
    response = view_func(request, *args, **kwargs)
  File "/usr/local/lib/python3.10/site-packages/django/contrib/admin/sites.py", line 241, in inner
    return view(request, *args, **kwargs)
  File "/usr/local/lib/python3.10/site-packages/django/utils/decorators.py", line 48, in _wrapper
    return bound_method(*args, **kwargs)
  File "/usr/local/lib/python3.10/site-packages/django/utils/decorators.py", line 188, in _view_wrapper
    result = _process_exception(request, e)
  File "/usr/local/lib/python3.10/site-packages/django/utils/decorators.py", line 186, in _view_wrapper
    response = view_func(request, *args, **kwargs)
  File "/usr/local/lib/python3.10/site-packages/django/contrib/admin/options.py", line 2001, in changelist_view
    cl = self.get_changelist_instance(request)
  File "/usr/local/lib/python3.10/site-packages/django/contrib/admin/options.py", line 866, in get_changelist_instance
    return ChangeList(
  File "/usr/local/lib/python3.10/site-packages/django/contrib/admin/views/main.py", line 91, in __init__
    self.root_queryset = model_admin.get_queryset(request)
  File "/app/api/admin.py", line 63, in wrapper
    result = func(self, request, *args, **kwargs)
  File "/app/api/admin.py", line 1038, in get_queryset
    return super().get_queryset(request).select_related('direccion').annotate(
  File "/usr/local/lib/python3.10/site-packages/django/db/models/query.py", line 1630, in annotate
    return self._annotate(args, kwargs, select=True)
  File "/usr/local/lib/python3.10/site-packages/django/db/models/query.py", line 1680, in _annotate
    clone.query.add_annotation(
  File "/usr/local/lib/python3.10/site-packages/django/db/models/sql/query.py", line 1194, in add_annotation
    annotation = annotation.resolve_expression(self, allow_joins=True, reuse=None)
  File "/usr/local/lib/python3.10/site-packages/django/db/models/expressions.py", line 753, in resolve_expression
    lhs = self.lhs.resolve_expression(
  File "/usr/local/lib/python3.10/site-packages/django/db/models/aggregates.py", line 63, in resolve_expression
    c = super().resolve_expression(query, allow_joins, reuse, summarize)
  File "/usr/local/lib/python3.10/site-packages/django/db/models/expressions.py", line 1073, in resolve_expression
    c.source_expressions[pos] = arg.resolve_expression(
  File "/usr/local/lib/python3.10/site-packages/django/db/models/expressions.py", line 895, in resolve_expression
    return query.resolve_ref(self.name, allow_joins, reuse, summarize)
  File "/usr/local/lib/python3.10/site-packages/django/db/models/sql/query.py", line 2010, in resolve_ref
    join_info = self.setup_joins(
  File "/usr/local/lib/python3.10/site-packages/django/db/models/sql/query.py", line 1863, in setup_joins
    path, final_field, targets, rest = self.names_to_path(
  File "/usr/local/lib/python3.10/site-packages/django/db/models/sql/query.py", line 1768, in names_to_path
    raise FieldError(
django.core.exceptions.FieldError: Cannot resolve keyword 'reservas_recogida' into field. Choices are: created_at, devoluciones, direccion, direccion_id, email, icono_url, id, latitud, longitud, nombre, recogidas, telefono, updated_at
ERROR 2025-05-28 17:27:01,907 log 20 140426962118464 Internal Server Error: /api/vehiculos/
Traceback (most recent call last):
  File "/usr/local/lib/python3.10/site-packages/django/core/handlers/exception.py", line 55, in inner
    response = get_response(request)
  File "/usr/local/lib/python3.10/site-packages/django/core/handlers/base.py", line 197, in _get_response
    response = wrapped_callback(request, *callback_args, **callback_kwargs)
  File "/usr/local/lib/python3.10/site-packages/django/views/decorators/csrf.py", line 65, in _view_wrapper
    return view_func(request, *args, **kwargs)
  File "/usr/local/lib/python3.10/site-packages/rest_framework/viewsets.py", line 125, in view
    return self.dispatch(request, *args, **kwargs)
  File "/usr/local/lib/python3.10/site-packages/rest_framework/views.py", line 515, in dispatch
    response = self.handle_exception(exc)
  File "/usr/local/lib/python3.10/site-packages/rest_framework/views.py", line 475, in handle_exception
    self.raise_uncaught_exception(exc)
  File "/usr/local/lib/python3.10/site-packages/rest_framework/views.py", line 486, in raise_uncaught_exception
    raise exc
  File "/usr/local/lib/python3.10/site-packages/rest_framework/views.py", line 512, in dispatch
    response = handler(request, *args, **kwargs)
  File "/app/api/views/vehiculos.py", line 83, in list
    'results': serializer.data,
  File "/usr/local/lib/python3.10/site-packages/rest_framework/serializers.py", line 797, in data
    ret = super().data
  File "/usr/local/lib/python3.10/site-packages/rest_framework/serializers.py", line 251, in data
    self._data = self.to_representation(self.instance)
  File "/usr/local/lib/python3.10/site-packages/rest_framework/serializers.py", line 715, in to_representation
    return [
  File "/usr/local/lib/python3.10/site-packages/rest_framework/serializers.py", line 716, in <listcomp>
    self.child.to_representation(item) for item in iterable
  File "/usr/local/lib/python3.10/site-packages/rest_framework/serializers.py", line 525, in to_representation
    for field in fields:
  File "/usr/local/lib/python3.10/site-packages/rest_framework/serializers.py", line 386, in _readable_fields
    for field in self.fields.values():
  File "/usr/local/lib/python3.10/site-packages/django/utils/functional.py", line 47, in __get__
    res = instance.__dict__[self.name] = self.func(instance)
  File "/usr/local/lib/python3.10/site-packages/rest_framework/serializers.py", line 374, in fields
    for key, value in self.get_fields().items():
  File "/usr/local/lib/python3.10/site-packages/rest_framework/serializers.py", line 1105, in get_fields
    field_class, field_kwargs = self.build_field(
  File "/usr/local/lib/python3.10/site-packages/rest_framework/serializers.py", line 1251, in build_field
    return self.build_unknown_field(field_name, model_class)
  File "/usr/local/lib/python3.10/site-packages/rest_framework/serializers.py", line 1369, in build_unknown_field
    raise ImproperlyConfigured(
django.core.exceptions.ImproperlyConfigured: Field name `descripcion` is not valid for model `Vehiculo` in `api.serializers.vehiculos.VehiculoListSerializer`.
ERROR 2025-05-28 17:27:15,930 log 21 140426962118464 Internal Server Error: /api/vehiculos/
Traceback (most recent call last):
  File "/usr/local/lib/python3.10/site-packages/django/core/handlers/exception.py", line 55, in inner
    response = get_response(request)
  File "/usr/local/lib/python3.10/site-packages/django/core/handlers/base.py", line 197, in _get_response
    response = wrapped_callback(request, *callback_args, **callback_kwargs)
  File "/usr/local/lib/python3.10/site-packages/django/views/decorators/csrf.py", line 65, in _view_wrapper
    return view_func(request, *args, **kwargs)
  File "/usr/local/lib/python3.10/site-packages/rest_framework/viewsets.py", line 125, in view
    return self.dispatch(request, *args, **kwargs)
  File "/usr/local/lib/python3.10/site-packages/rest_framework/views.py", line 515, in dispatch
    response = self.handle_exception(exc)
  File "/usr/local/lib/python3.10/site-packages/rest_framework/views.py", line 475, in handle_exception
    self.raise_uncaught_exception(exc)
  File "/usr/local/lib/python3.10/site-packages/rest_framework/views.py", line 486, in raise_uncaught_exception
    raise exc
  File "/usr/local/lib/python3.10/site-packages/rest_framework/views.py", line 512, in dispatch
    response = handler(request, *args, **kwargs)
  File "/app/api/views/vehiculos.py", line 83, in list
    'results': serializer.data,
  File "/usr/local/lib/python3.10/site-packages/rest_framework/serializers.py", line 797, in data
    ret = super().data
  File "/usr/local/lib/python3.10/site-packages/rest_framework/serializers.py", line 251, in data
    self._data = self.to_representation(self.instance)
  File "/usr/local/lib/python3.10/site-packages/rest_framework/serializers.py", line 715, in to_representation
    return [
  File "/usr/local/lib/python3.10/site-packages/rest_framework/serializers.py", line 716, in <listcomp>
    self.child.to_representation(item) for item in iterable
  File "/usr/local/lib/python3.10/site-packages/rest_framework/serializers.py", line 525, in to_representation
    for field in fields:
  File "/usr/local/lib/python3.10/site-packages/rest_framework/serializers.py", line 386, in _readable_fields
    for field in self.fields.values():
  File "/usr/local/lib/python3.10/site-packages/django/utils/functional.py", line 47, in __get__
    res = instance.__dict__[self.name] = self.func(instance)
  File "/usr/local/lib/python3.10/site-packages/rest_framework/serializers.py", line 374, in fields
    for key, value in self.get_fields().items():
  File "/usr/local/lib/python3.10/site-packages/rest_framework/serializers.py", line 1105, in get_fields
    field_class, field_kwargs = self.build_field(
  File "/usr/local/lib/python3.10/site-packages/rest_framework/serializers.py", line 1251, in build_field
    return self.build_unknown_field(field_name, model_class)
  File "/usr/local/lib/python3.10/site-packages/rest_framework/serializers.py", line 1369, in build_unknown_field
    raise ImproperlyConfigured(
django.core.exceptions.ImproperlyConfigured: Field name `descripcion` is not valid for model `Vehiculo` in `api.serializers.vehiculos.VehiculoListSerializer`.
ERROR 2025-05-28 17:39:20,242 log 22 140426962118464 Internal Server Error: /api/vehiculos/
Traceback (most recent call last):
  File "/usr/local/lib/python3.10/site-packages/django/core/handlers/exception.py", line 55, in inner
    response = get_response(request)
  File "/usr/local/lib/python3.10/site-packages/django/core/handlers/base.py", line 197, in _get_response
    response = wrapped_callback(request, *callback_args, **callback_kwargs)
  File "/usr/local/lib/python3.10/site-packages/django/views/decorators/csrf.py", line 65, in _view_wrapper
    return view_func(request, *args, **kwargs)
  File "/usr/local/lib/python3.10/site-packages/rest_framework/viewsets.py", line 125, in view
    return self.dispatch(request, *args, **kwargs)
  File "/usr/local/lib/python3.10/site-packages/rest_framework/views.py", line 515, in dispatch
    response = self.handle_exception(exc)
  File "/usr/local/lib/python3.10/site-packages/rest_framework/views.py", line 475, in handle_exception
    self.raise_uncaught_exception(exc)
  File "/usr/local/lib/python3.10/site-packages/rest_framework/views.py", line 486, in raise_uncaught_exception
    raise exc
  File "/usr/local/lib/python3.10/site-packages/rest_framework/views.py", line 512, in dispatch
    response = handler(request, *args, **kwargs)
  File "/app/api/views/vehiculos.py", line 83, in list
    'results': serializer.data,
  File "/usr/local/lib/python3.10/site-packages/rest_framework/serializers.py", line 797, in data
    ret = super().data
  File "/usr/local/lib/python3.10/site-packages/rest_framework/serializers.py", line 251, in data
    self._data = self.to_representation(self.instance)
  File "/usr/local/lib/python3.10/site-packages/rest_framework/serializers.py", line 715, in to_representation
    return [
  File "/usr/local/lib/python3.10/site-packages/rest_framework/serializers.py", line 716, in <listcomp>
    self.child.to_representation(item) for item in iterable
  File "/usr/local/lib/python3.10/site-packages/rest_framework/serializers.py", line 525, in to_representation
    for field in fields:
  File "/usr/local/lib/python3.10/site-packages/rest_framework/serializers.py", line 386, in _readable_fields
    for field in self.fields.values():
  File "/usr/local/lib/python3.10/site-packages/django/utils/functional.py", line 47, in __get__
    res = instance.__dict__[self.name] = self.func(instance)
  File "/usr/local/lib/python3.10/site-packages/rest_framework/serializers.py", line 374, in fields
    for key, value in self.get_fields().items():
  File "/usr/local/lib/python3.10/site-packages/rest_framework/serializers.py", line 1105, in get_fields
    field_class, field_kwargs = self.build_field(
  File "/usr/local/lib/python3.10/site-packages/rest_framework/serializers.py", line 1251, in build_field
    return self.build_unknown_field(field_name, model_class)
  File "/usr/local/lib/python3.10/site-packages/rest_framework/serializers.py", line 1369, in build_unknown_field
    raise ImproperlyConfigured(
django.core.exceptions.ImproperlyConfigured: Field name `descripcion` is not valid for model `Vehiculo` in `api.serializers.vehiculos.VehiculoListSerializer`.
ERROR 2025-05-28 17:40:55,455 log 21 140426962118464 Internal Server Error: /api/vehiculos/
Traceback (most recent call last):
  File "/usr/local/lib/python3.10/site-packages/django/core/handlers/exception.py", line 55, in inner
    response = get_response(request)
  File "/usr/local/lib/python3.10/site-packages/django/core/handlers/base.py", line 197, in _get_response
    response = wrapped_callback(request, *callback_args, **callback_kwargs)
  File "/usr/local/lib/python3.10/site-packages/django/views/decorators/csrf.py", line 65, in _view_wrapper
    return view_func(request, *args, **kwargs)
  File "/usr/local/lib/python3.10/site-packages/rest_framework/viewsets.py", line 125, in view
    return self.dispatch(request, *args, **kwargs)
  File "/usr/local/lib/python3.10/site-packages/rest_framework/views.py", line 515, in dispatch
    response = self.handle_exception(exc)
  File "/usr/local/lib/python3.10/site-packages/rest_framework/views.py", line 475, in handle_exception
    self.raise_uncaught_exception(exc)
  File "/usr/local/lib/python3.10/site-packages/rest_framework/views.py", line 486, in raise_uncaught_exception
    raise exc
  File "/usr/local/lib/python3.10/site-packages/rest_framework/views.py", line 512, in dispatch
    response = handler(request, *args, **kwargs)
  File "/app/api/views/vehiculos.py", line 83, in list
    'results': serializer.data,
  File "/usr/local/lib/python3.10/site-packages/rest_framework/serializers.py", line 797, in data
    ret = super().data
  File "/usr/local/lib/python3.10/site-packages/rest_framework/serializers.py", line 251, in data
    self._data = self.to_representation(self.instance)
  File "/usr/local/lib/python3.10/site-packages/rest_framework/serializers.py", line 715, in to_representation
    return [
  File "/usr/local/lib/python3.10/site-packages/rest_framework/serializers.py", line 716, in <listcomp>
    self.child.to_representation(item) for item in iterable
  File "/usr/local/lib/python3.10/site-packages/rest_framework/serializers.py", line 525, in to_representation
    for field in fields:
  File "/usr/local/lib/python3.10/site-packages/rest_framework/serializers.py", line 386, in _readable_fields
    for field in self.fields.values():
  File "/usr/local/lib/python3.10/site-packages/django/utils/functional.py", line 47, in __get__
    res = instance.__dict__[self.name] = self.func(instance)
  File "/usr/local/lib/python3.10/site-packages/rest_framework/serializers.py", line 374, in fields
    for key, value in self.get_fields().items():
  File "/usr/local/lib/python3.10/site-packages/rest_framework/serializers.py", line 1105, in get_fields
    field_class, field_kwargs = self.build_field(
  File "/usr/local/lib/python3.10/site-packages/rest_framework/serializers.py", line 1251, in build_field
    return self.build_unknown_field(field_name, model_class)
  File "/usr/local/lib/python3.10/site-packages/rest_framework/serializers.py", line 1369, in build_unknown_field
    raise ImproperlyConfigured(
django.core.exceptions.ImproperlyConfigured: Field name `descripcion` is not valid for model `Vehiculo` in `api.serializers.vehiculos.VehiculoListSerializer`.
WARNING 2025-05-28 18:06:13,652 log 22 140184472233792 Not Found: /api/reservations/create_new
WARNING 2025-05-28 18:19:30,692 log 22 140184472233792 Not Found: /api/reservations/create_new
INFO 2025-05-28 18:31:56,472 services 23 140460161791808 StripePaymentService inicializado
WARNING 2025-05-28 18:31:56,479 log 23 140460161791808 Bad Request: /api/reservations/create-new/
INFO 2025-05-28 19:13:37,705 services 21 140265569236800 StripePaymentService inicializado
WARNING 2025-05-28 19:13:37,714 log 21 140265569236800 Bad Request: /api/reservations/create-new/
INFO 2025-05-28 20:08:34,860 services 20 140719293028160 StripePaymentService inicializado
WARNING 2025-05-28 20:08:34,885 log 20 140719293028160 Bad Request: /api/reservations/create-new/
INFO 2025-05-28 20:43:36,209 services 23 140095555467072 StripePaymentService inicializado
WARNING 2025-05-28 20:43:36,252 log 23 140095555467072 Bad Request: /api/reservations/create-new/
